<?xml version="1.0" ?>
<!-- =================================================================================== -->
<!-- |    This document was autogenerated by xacro from ./src/boxygo_description/urdf/luksusowy.urdf.xacro | -->
<!-- |    EDITING THIS FILE BY HAND IS NOT RECOMMENDED                                 | -->
<!-- =================================================================================== -->
<robot name="delivery_robot">
  <!-- MATERIAÅY -->
  <material name="black">
    <color rgba="0.0 0.0 0.0 1.0"/>
  </material>
  <material name="white">
    <color rgba="0.7 0.7 0.7 0.5"/>
  </material>
  <material name="grey">
    <color rgba="0.4 0.4 0.4 1.0"/>
  </material>
  <material name="darkgrey">
    <color rgba="0.05 0.05 0.05 1.0"/>
  </material>
  <!-- BASE LINK -->
  <link name="base_link">
    <visual>
      <origin rpy="0 0 0" xyz="0 0 0"/>
      <geometry>
        <mesh filename="package://boxygo_description/meshes/frame_full.stl" scale="0.001 0.001 0.001"/>
      </geometry>
      <material name="darkgrey"/>
    </visual>
    <collision>
      <origin rpy="0 0 0" xyz="0 0 0"/>
      <geometry>
        <mesh filename="package://boxygo_description/meshes/frame_full.stl" scale="0.001 0.001 0.001"/>
      </geometry>
    </collision>
    <inertial>
      <mass value="23.972607"/>
      <origin rpy="0 0 0" xyz="-0.020386 0 0.075697"/>
      <inertia ixx="1.293" ixy="-0.00005897" ixz="0.07241" iyy="1.521" iyz="0.0000000617" izz="2.615"/>
    </inertial>
  </link>
  <!-- RIGHT ROCKER BEAM -->
  <link name="right_rocker_beam">
    <visual>
      <geometry>
        <mesh filename="package://boxygo_description/meshes/beam_full.stl" scale="0.001 0.001 0.001"/>
      </geometry>
      <origin rpy="0 0 0" xyz="0 0 0"/>
      <material name="black"/>
    </visual>
    <collision>
      <geometry>
        <mesh filename="package://boxygo_description/meshes/beam_full.stl" scale="0.001 0.001 0.001"/>
      </geometry>
      <origin rpy="0 0 0" xyz="0 0 0"/>
    </collision>
    <inertial>
      <mass value="3.38412"/>
      <origin rpy="0 0 0" xyz="-0.000000009 -0.027628 -0.071329"/>
      <inertia ixx="0.01030" ixy="1e-12" ixz="-5e-12" iyy="0.05174" iyz="-0.002614" izz="0.04833"/>
    </inertial>
  </link>
  <!-- LEFT ROCKER BEAM -->
  <link name="left_rocker_beam">
    <visual>
      <geometry>
        <mesh filename="package://boxygo_description/meshes/beam_full.stl" scale="0.001 0.001 0.001"/>
      </geometry>
      <origin rpy="0 0 0" xyz="0 0 0"/>
      <material name="black"/>
    </visual>
    <collision>
      <geometry>
        <mesh filename="package://boxygo_description/meshes/beam_full.stl" scale="0.001 0.001 0.001"/>
      </geometry>
      <origin rpy="0 0 0" xyz="0 0 0"/>
    </collision>
    <inertial>
      <mass value="3.38412"/>
      <origin rpy="0 0 0" xyz="-0.000000009 -0.027628 -0.071329"/>
      <inertia ixx="0.01030" ixy="1e-12" ixz="-5e-12" iyy="0.05174" iyz="-0.002614" izz="0.04833"/>
    </inertial>
  </link>
  <joint name="right_rocker_beam_joint" type="revolute">
    <parent link="base_link"/>
    <child link="right_rocker_beam"/>
    <origin rpy="0 0 0" xyz="-0.13 -0.22085 0.0876"/>
    <axis xyz="0 1 0"/>
    <limit effort="50.0" lower="-0.2617993877991494" upper="0.2617993877991494" velocity="10.0"/>
    <dynamics damping="0.05" friction="0.005"/>
  </joint>
  <joint name="left_rocker_beam_joint" type="revolute">
    <parent link="base_link"/>
    <child link="left_rocker_beam"/>
    <origin rpy="0 0 3.141592653589793" xyz="-0.13 0.22085 0.0876"/>
    <axis xyz="0 1 0"/>
    <limit effort="50.0" lower="-0.2617993877991494" upper="0.2617993877991494" velocity="10.0"/>
    <dynamics damping="0.05" friction="0.005"/>
  </joint>
  <link name="left_wheel_1">
    <visual>
      <geometry>
        <mesh filename="package://boxygo_description/meshes/wheel.stl" scale="0.001 0.001 0.001"/>
      </geometry>
      <origin rpy="0 0 0" xyz="0 0 0"/>
      <material name="black"/>
    </visual>
    <collision>
      <geometry>
        <mesh filename="package://boxygo_description/meshes/wheel.dae" scale="0.001 0.001 0.001"/>
      </geometry>
      <origin rpy="0 0 0" xyz="0 0 0"/>
    </collision>
    <inertial>
      <mass value="1.341411"/>
      <origin rpy="0 0 0" xyz="0.000003 0.005392 0.000000"/>
      <inertia ixx="0.002637" ixy="1.18e-9" ixz="8.32e-9" iyy="0.004379" iyz="-3.867e-9" izz="0.002637"/>
    </inertial>
  </link>
  <joint name="left_wheel_1_joint" type="continuous">
    <parent link="base_link"/>
    <child link="left_wheel_1"/>
    <origin rpy="0 0 3.141592653589793" xyz="0.26 0.275 -0.0106"/>
    <axis xyz="0 -1 0"/>
    <limit effort="12.0" velocity="50.26548245743669"/>
    <dynamics damping="0.01" friction="0.001"/>
  </joint>
  <link name="left_wheel_2">
    <visual>
      <geometry>
        <mesh filename="package://boxygo_description/meshes/wheel.stl" scale="0.001 0.001 0.001"/>
      </geometry>
      <origin rpy="0 0 0" xyz="0 0 0"/>
      <material name="black"/>
    </visual>
    <collision>
      <geometry>
        <mesh filename="package://boxygo_description/meshes/wheel.dae" scale="0.001 0.001 0.001"/>
      </geometry>
      <origin rpy="0 0 0" xyz="0 0 0"/>
    </collision>
    <inertial>
      <mass value="1.341411"/>
      <origin rpy="0 0 0" xyz="0.000003 0.005392 0.000000"/>
      <inertia ixx="0.002637" ixy="1.18e-9" ixz="8.32e-9" iyy="0.004379" iyz="-3.867e-9" izz="0.002637"/>
    </inertial>
  </link>
  <joint name="left_wheel_2_joint" type="continuous">
    <parent link="left_rocker_beam"/>
    <child link="left_wheel_2"/>
    <origin rpy="0 0 0.0" xyz="-0.13 -0.05415 -0.0982"/>
    <axis xyz="0 -1 0"/>
    <limit effort="12.0" velocity="50.26548245743669"/>
    <dynamics damping="0.01" friction="0.001"/>
  </joint>
  <link name="left_wheel_3">
    <visual>
      <geometry>
        <mesh filename="package://boxygo_description/meshes/wheel.stl" scale="0.001 0.001 0.001"/>
      </geometry>
      <origin rpy="0 0 0" xyz="0 0 0"/>
      <material name="black"/>
    </visual>
    <collision>
      <geometry>
        <mesh filename="package://boxygo_description/meshes/wheel.dae" scale="0.001 0.001 0.001"/>
      </geometry>
      <origin rpy="0 0 0" xyz="0 0 0"/>
    </collision>
    <inertial>
      <mass value="1.341411"/>
      <origin rpy="0 0 0" xyz="0.000003 0.005392 0.000000"/>
      <inertia ixx="0.002637" ixy="1.18e-9" ixz="8.32e-9" iyy="0.004379" iyz="-3.867e-9" izz="0.002637"/>
    </inertial>
  </link>
  <joint name="left_wheel_3_joint" type="continuous">
    <parent link="left_rocker_beam"/>
    <child link="left_wheel_3"/>
    <origin rpy="0 0 0.0" xyz="0.13 -0.05415 -0.0982"/>
    <axis xyz="0 -1 0"/>
    <limit effort="12.0" velocity="50.26548245743669"/>
    <dynamics damping="0.01" friction="0.001"/>
  </joint>
  <link name="right_wheel_1">
    <visual>
      <geometry>
        <mesh filename="package://boxygo_description/meshes/wheel.stl" scale="0.001 0.001 0.001"/>
      </geometry>
      <origin rpy="0 0 0" xyz="0 0 0"/>
      <material name="black"/>
    </visual>
    <collision>
      <geometry>
        <mesh filename="package://boxygo_description/meshes/wheel.dae" scale="0.001 0.001 0.001"/>
      </geometry>
      <origin rpy="0 0 0" xyz="0 0 0"/>
    </collision>
    <inertial>
      <mass value="1.341411"/>
      <origin rpy="0 0 0" xyz="0.000003 0.005392 0.000000"/>
      <inertia ixx="0.002637" ixy="1.18e-9" ixz="8.32e-9" iyy="0.004379" iyz="-3.867e-9" izz="0.002637"/>
    </inertial>
  </link>
  <joint name="right_wheel_1_joint" type="continuous">
    <parent link="base_link"/>
    <child link="right_wheel_1"/>
    <origin rpy="0 0 0.0" xyz="0.26 -0.275 -0.0106"/>
    <axis xyz="0 1 0"/>
    <limit effort="12.0" velocity="50.26548245743669"/>
    <dynamics damping="0.01" friction="0.001"/>
  </joint>
  <link name="right_wheel_2">
    <visual>
      <geometry>
        <mesh filename="package://boxygo_description/meshes/wheel.stl" scale="0.001 0.001 0.001"/>
      </geometry>
      <origin rpy="0 0 0" xyz="0 0 0"/>
      <material name="black"/>
    </visual>
    <collision>
      <geometry>
        <mesh filename="package://boxygo_description/meshes/wheel.dae" scale="0.001 0.001 0.001"/>
      </geometry>
      <origin rpy="0 0 0" xyz="0 0 0"/>
    </collision>
    <inertial>
      <mass value="1.341411"/>
      <origin rpy="0 0 0" xyz="0.000003 0.005392 0.000000"/>
      <inertia ixx="0.002637" ixy="1.18e-9" ixz="8.32e-9" iyy="0.004379" iyz="-3.867e-9" izz="0.002637"/>
    </inertial>
  </link>
  <joint name="right_wheel_2_joint" type="continuous">
    <parent link="right_rocker_beam"/>
    <child link="right_wheel_2"/>
    <origin rpy="0 0 0.0" xyz="0.13 -0.05415 -0.0982"/>
    <axis xyz="0 1 0"/>
    <limit effort="12.0" velocity="50.26548245743669"/>
    <dynamics damping="0.01" friction="0.001"/>
  </joint>
  <link name="right_wheel_3">
    <visual>
      <geometry>
        <mesh filename="package://boxygo_description/meshes/wheel.stl" scale="0.001 0.001 0.001"/>
      </geometry>
      <origin rpy="0 0 0" xyz="0 0 0"/>
      <material name="black"/>
    </visual>
    <collision>
      <geometry>
        <mesh filename="package://boxygo_description/meshes/wheel.dae" scale="0.001 0.001 0.001"/>
      </geometry>
      <origin rpy="0 0 0" xyz="0 0 0"/>
    </collision>
    <inertial>
      <mass value="1.341411"/>
      <origin rpy="0 0 0" xyz="0.000003 0.005392 0.000000"/>
      <inertia ixx="0.002637" ixy="1.18e-9" ixz="8.32e-9" iyy="0.004379" iyz="-3.867e-9" izz="0.002637"/>
    </inertial>
  </link>
  <joint name="right_wheel_3_joint" type="continuous">
    <parent link="right_rocker_beam"/>
    <child link="right_wheel_3"/>
    <origin rpy="0 0 0.0" xyz="-0.13 -0.05415 -0.0982"/>
    <axis xyz="0 1 0"/>
    <limit effort="12.0" velocity="50.26548245743669"/>
    <dynamics damping="0.01" friction="0.001"/>
  </joint>
  <ros2_control name="TopicBasedSystem" type="system">
    <hardware>
      <plugin>topic_based_ros2_control/TopicBasedSystem</plugin>
      <param name="joint_commands_topic">/isaac_joint_commands</param>
      <param name="joint_states_topic">/isaac_joint_states</param>
      <param name="sum_wrapped_joint_states">true</param>
      <param name="provide_odom_frame">false</param>
      <param name="publish_odom">false</param>
      <param name="publish_odom_tf">false</param>
    </hardware>
    <joint name="left_wheel_1_joint">
      <command_interface name="velocity"/>
      <state_interface name="position"/>
      <state_interface name="velocity"/>
    </joint>
    <joint name="left_wheel_2_joint">
      <command_interface name="velocity"/>
      <state_interface name="position"/>
      <state_interface name="velocity"/>
    </joint>
    <joint name="left_wheel_3_joint">
      <command_interface name="velocity"/>
      <state_interface name="position"/>
      <state_interface name="velocity"/>
    </joint>
    <joint name="right_wheel_1_joint">
      <command_interface name="velocity"/>
      <state_interface name="position"/>
      <state_interface name="velocity"/>
    </joint>
    <joint name="right_wheel_2_joint">
      <command_interface name="velocity"/>
      <state_interface name="position"/>
      <state_interface name="velocity"/>
    </joint>
    <joint name="right_wheel_3_joint">
      <command_interface name="velocity"/>
      <state_interface name="position"/>
      <state_interface name="velocity"/>
    </joint>
    <joint name="left_rocker_beam_joint">
      <command_interface name="velocity"/>
      <state_interface name="position"/>
      <state_interface name="velocity"/>
    </joint>
    <joint name="right_rocker_beam_joint">
      <command_interface name="velocity"/>
      <state_interface name="position"/>
      <state_interface name="velocity"/>
    </joint>
  </ros2_control>
  <material name="aluminum">
    <color rgba="0.5 0.5 0.5 1"/>
  </material>
  <material name="plastic">
    <color rgba="0.1 0.1 0.1 1"/>
  </material>
  <joint name="laser_joint" type="fixed">
    <parent link="base_link"/>
    <child link="laser_frame"/>
    <origin rpy="0 0 3.173" xyz="0.06 0.0 0.32"/>
  </joint>
  <link name="laser_frame">
    <visual>
      <origin rpy="0 0 0" xyz="0 0 0"/>
      <geometry>
        <cylinder length="0.04" radius="0.035"/>
      </geometry>
      <material name="black"/>
    </visual>
    <collision>
      <origin rpy="0 0 0" xyz="0 0 0"/>
      <geometry>
        <cylinder length="0.04" radius="0.035"/>
      </geometry>
    </collision>
    <inertial>
      <mass value="0.2"/>
      <origin rpy="0 0 0" xyz="0 0 0"/>
      <inertia ixx="0.0001" ixy="0" ixz="0" iyy="0.0001" iyz="0" izz="0.0001"/>
    </inertial>
  </link>
  <gazebo reference="laser_frame">
    <sensor name="lidar" type="ray">
      <always_on>true</always_on>
      <visualize>false</visualize>
      <update_rate>8</update_rate>
      <ray>
        <scan>
          <horizontal>
            <samples>560</samples>
            <resolution>1</resolution>
            <min_angle>-3.14</min_angle>
            <max_angle>3.14</max_angle>
          </horizontal>
        </scan>
        <range>
          <min>0.08</min>
          <max>12.0</max>
          <resolution>0.0017</resolution>
        </range>
        <noise>
          <type>gaussian</type>
          <mean>0.0</mean>
          <stddev>0.01</stddev>
        </noise>
      </ray>
      <plugin filename="libgazebo_ros_ray_sensor.so" name="scan">
        <ros>
          <remapping>~/out:=/scan</remapping>
        </ros>
        <output_type>sensor_msgs/LaserScan</output_type>
        <frame_name>laser_frame</frame_name>
      </plugin>
    </sensor>
    <material>Gazebo/Black</material>
  </gazebo>
  <!-- camera body, with origin at bottom screw mount -->
  <joint name="camera_joint" type="fixed">
    <origin rpy="0 0 0" xyz="0.38 0.0 0.225"/>
    <parent link="base_link"/>
    <child link="camera_bottom_screw_frame"/>
  </joint>
  <link name="camera_bottom_screw_frame"/>
  <joint name="camera_link_joint" type="fixed">
    <origin rpy="0 0 0" xyz="0.010600000000000002 0.0175 0.0125"/>
    <parent link="camera_bottom_screw_frame"/>
    <child link="camera_link"/>
  </joint>
  <link name="camera_link">
    <visual>
      <!-- the mesh origin is at front plate in between the two infrared camera axes -->
      <origin rpy="1.5707963267948966 0 1.5707963267948966" xyz="0.0043 -0.0175 0"/>
      <geometry>
        <mesh filename="package://realsense2_description/meshes/d435.dae"/>
      </geometry>
    </visual>
    <collision>
      <origin rpy="0 0 0" xyz="0 -0.0175 0"/>
      <geometry>
        <box size="0.02505 0.09 0.025"/>
      </geometry>
    </collision>
    <inertial>
      <!-- The following are not reliable values, and should not be used for modeling -->
      <mass value="0.072"/>
      <origin xyz="0 0 0"/>
      <inertia ixx="0.003881243" ixy="0.0" ixz="0.0" iyy="0.000498940" iyz="0.0" izz="0.003879257"/>
    </inertial>
  </link>
  <!-- camera depth joints and links -->
  <joint name="camera_depth_joint" type="fixed">
    <origin rpy="0 0 0" xyz="0 0 0"/>
    <parent link="camera_link"/>
    <child link="camera_depth_frame"/>
  </joint>
  <link name="camera_depth_frame"/>
  <joint name="camera_depth_optical_joint" type="fixed">
    <origin rpy="-1.5707963267948966 0 -1.5707963267948966" xyz="0 0 0"/>
    <parent link="camera_depth_frame"/>
    <child link="camera_depth_optical_frame"/>
  </joint>
  <link name="camera_depth_optical_frame"/>
  <!-- camera left IR joints and links -->
  <joint name="camera_infra1_joint" type="fixed">
    <origin rpy="0 0 0" xyz="0 0.0 0"/>
    <parent link="camera_link"/>
    <child link="camera_infra1_frame"/>
  </joint>
  <link name="camera_infra1_frame"/>
  <joint name="camera_infra1_optical_joint" type="fixed">
    <origin rpy="-1.5707963267948966 0 -1.5707963267948966" xyz="0 0 0"/>
    <parent link="camera_infra1_frame"/>
    <child link="camera_infra1_optical_frame"/>
  </joint>
  <link name="camera_infra1_optical_frame"/>
  <!-- camera right IR joints and links -->
  <joint name="camera_infra2_joint" type="fixed">
    <origin rpy="0 0 0" xyz="0 -0.05 0"/>
    <parent link="camera_link"/>
    <child link="camera_infra2_frame"/>
  </joint>
  <link name="camera_infra2_frame"/>
  <joint name="camera_infra2_optical_joint" type="fixed">
    <origin rpy="-1.5707963267948966 0 -1.5707963267948966" xyz="0 0 0"/>
    <parent link="camera_infra2_frame"/>
    <child link="camera_infra2_optical_frame"/>
  </joint>
  <link name="camera_infra2_optical_frame"/>
  <!-- camera color joints and links -->
  <joint name="camera_color_joint" type="fixed">
    <origin rpy="0 0 0" xyz="0 0.015 0"/>
    <parent link="camera_link"/>
    <child link="camera_color_frame"/>
  </joint>
  <link name="camera_color_frame"/>
  <joint name="camera_color_optical_joint" type="fixed">
    <origin rpy="-1.5707963267948966 0 -1.5707963267948966" xyz="0 0 0"/>
    <parent link="camera_color_frame"/>
    <child link="camera_color_optical_frame"/>
  </joint>
  <link name="camera_color_optical_frame"/>
  <link name="camera_accel_frame"/>
  <link name="camera_accel_optical_frame"/>
  <link name="camera_gyro_frame"/>
  <link name="camera_gyro_optical_frame"/>
  <joint name="camera_accel_joint" type="fixed">
    <origin rpy="0 0 0" xyz="-0.01174 -0.00552 0.0051"/>
    <parent link="camera_link"/>
    <child link="camera_accel_frame"/>
  </joint>
  <joint name="camera_accel_optical_joint" type="fixed">
    <origin rpy="-1.5707963267948966 0 -1.5707963267948966" xyz="0 0 0"/>
    <parent link="camera_accel_frame"/>
    <child link="camera_accel_optical_frame"/>
  </joint>
  <joint name="camera_gyro_joint" type="fixed">
    <origin rpy="0 0 0" xyz="-0.01174 -0.00552 0.0051"/>
    <parent link="camera_link"/>
    <child link="camera_gyro_frame"/>
  </joint>
  <joint name="camera_gyro_optical_joint" type="fixed">
    <origin rpy="-1.5707963267948966 0 -1.5707963267948966" xyz="0 0 0"/>
    <parent link="camera_gyro_frame"/>
    <child link="camera_gyro_optical_frame"/>
  </joint>
</robot>
