<?xml version="1.0" ?>
<!-- =================================================================================== -->
<!-- |    This document was autogenerated by xacro from robot_luksusowy.urdf.xacro     | -->
<!-- |    EDITING THIS FILE BY HAND IS NOT RECOMMENDED                                 | -->
<!-- =================================================================================== -->
<robot name="delivery_robot">
  <!-- Materiały -->
  <material name="black">
    <color rgba="0.0 0.0 0.0 1.0"/>
  </material>
  <material name="white">
    <color rgba="0.7 0.7 0.7 0.5"/>
  </material>
  <material name="grey">
    <color rgba="0.4 0.4 0.4 1.0"/>
  </material>
  <material name="darkgrey">
    <color rgba="0.05 0.05 0.05 1.0"/>
  </material>
  <!-- IMU sensor -->
  <link name="imu_link">
    <inertial>
      <mass value="0.01"/>
      <origin rpy="0 0 0" xyz="0 0 0"/>
      <inertia ixx="1e-5" ixy="0" ixz="0" iyy="1e-5" iyz="0" izz="1e-5"/>
    </inertial>
  </link>
  <joint name="imu_joint" type="fixed">
    <parent link="base_link"/>
    <child link="imu_link"/>
    <origin rpy="0 0 0" xyz="0 0 0.25"/>
  </joint>
  <gazebo reference="imu_link">
    <sensor name="imu_sensor" type="imu">
      <always_on>true</always_on>
      <update_rate>60.0</update_rate>
      <imu>
        <noise>
          <angular_velocity>
            <type>gaussian</type>
            <mean>0.0</mean>
            <stddev>0.001</stddev>
          </angular_velocity>
          <linear_acceleration>
            <type>gaussian</type>
            <mean>0.0</mean>
            <stddev>0.001</stddev>
          </linear_acceleration>
        </noise>
      </imu>
      <plugin filename="libgazebo_ros_imu_sensor.so" name="imu_plugin">
        <ros>
          <namespace>/</namespace>
          <remapping>~/out:=imu/data</remapping>
        </ros>
        <frame_name>imu_link</frame_name>
        <orientation>0.01 0 0  0 0.01 0  0 0 0.01</orientation>
        <angular_velocity>0.01 0 0  0 0.01 0  0 0 0.01</angular_velocity>
        <linear_acceleration>999 0 0  0 999 0  0 0 999</linear_acceleration>
      </plugin>
    </sensor>
  </gazebo>
  <!-- footprint-->
  <joint name="base_footprint_joint" type="fixed">
    <parent link="base_link"/>
    <child link="base_footprint"/>
    <origin rpy="0 0 0" xyz="0 0 0"/>
  </joint>
  <link name="base_footprint">
      </link>
  <!-- Kamera -->
  <link name="depth_camera_link">
    <visual>
      <geometry>
        <box size="0.02 0.09 0.03"/>
      </geometry>
      <material name="black"/>
    </visual>
    <collision>
      <geometry>
        <box size="0.02 0.09 0.03"/>
      </geometry>
    </collision>
    <inertial>
      <mass value="0.1"/>
      <inertia ixx="0.0001" ixy="0.0" ixz="0.0" iyy="0.0001" iyz="0.0" izz="0.0001"/>
    </inertial>
  </link>
  <joint name="depth_camera_joint" type="fixed">
    <parent link="base_link"/>
    <child link="depth_camera_link"/>
    <origin rpy="0 0 0" xyz="0.41500000000000004 0 0.15"/>
  </joint>
  <joint name="depth_camera_optical_joint" type="fixed">
    <parent link="depth_camera_link"/>
    <child link="depth_camera_link_optical"/>
    <origin rpy="-1.5708 0 -1.5708" xyz="0 0 0"/>
    <!-- -pi/2 in radians -->
  </joint>
  <link name="depth_camera_link_optical"/>
  <gazebo reference="depth_camera_link">
    <sensor name="depth_camera" type="depth">
      <pose>0 0 0 0 0 0</pose>
      <visualize>true</visualize>
      <update_rate>60.0</update_rate>
      <camera>
        <horizontal_fov>1.39626</horizontal_fov>
        <image>
          <width>640</width>
          <height>480</height>
          <format>B8G8R8</format>
        </image>
        <clip>
          <near>0.1</near>
          <far>10.0</far>
        </clip>
      </camera>
      <plugin filename="libgazebo_ros_camera.so" name="depth_camera_controller">
        <camera_name>depth_camera</camera_name>
        <frame_name>depth_camera_link_optical</frame_name>
        <min_depth>0.1</min_depth>
        <max_depth>100.0</max_depth>
      </plugin>
    </sensor>
  </gazebo>
  <!-- Lidar 2D -->
  <link name="lidar_link">
    <visual>
      <geometry>
        <cylinder length="0.05" radius="0.03"/>
      </geometry>
      <material name="black"/>
    </visual>
    <collision>
      <geometry>
        <cylinder length="0.05" radius="0.03"/>
      </geometry>
    </collision>
    <inertial>
      <mass value="0.2"/>
      <inertia ixx="0.0001" ixy="0" ixz="0" iyy="0.0001" iyz="0" izz="0.0001"/>
    </inertial>
  </link>
  <joint name="lidar_joint" type="fixed">
    <parent link="base_link"/>
    <child link="lidar_link"/>
    <origin rpy="0 0 0" xyz="0.375 0 0.275"/>
  </joint>
  <gazebo reference="lidar_link">
    <sensor name="lidar_sensor" type="ray">
      <always_on>true</always_on>
      <update_rate>60.0</update_rate>
      <visualize>false</visualize>
      <ray>
        <scan>
          <horizontal>
            <samples>360</samples>
            <resolution>1</resolution>
            <min_angle>-3.14159</min_angle>
            <max_angle>3.14159</max_angle>
          </horizontal>
        </scan>
        <range>
          <min>0.3</min>
          <max>12</max>
          <resolution>0.01</resolution>
        </range>
        <noise>
          <type>gaussian</type>
          <mean>0.0</mean>
          <stddev>0.01</stddev>
        </noise>
      </ray>
      <plugin filename="libgazebo_ros_ray_sensor.so" name="gazebo_ros_laser">
        <topicName>scan</topicName>
        <ros>
          <argument>~/out:=scan</argument>
        </ros>
        <output_type>sensor_msgs/LaserScan</output_type>
        <frameName>lidar_link</frameName>
      </plugin>
    </sensor>
  </gazebo>
  <gazebo reference="lidar_link">
    <material>Gazebo/Black</material>
  </gazebo>
  <gazebo reference="depth_camera_link">
    <material>Gazebo/Black</material>
  </gazebo>
  <!-- Rama -->
  <link name="base_link">
    <visual>
      <origin rpy="0 0 0" xyz="0 0 0"/>
      <geometry>
        <mesh filename="meshes/frame_full.stl" scale="0.001 0.001 0.001"/>
      </geometry>
      <material name="darkgrey"/>
    </visual>
    <collision>
      <origin rpy="0 0 0" xyz="0 0 0"/>
      <geometry>
        <mesh filename="meshes/frame_full.stl" scale="0.001 0.001 0.001"/>
      </geometry>
    </collision>
    <inertial>
      <mass value="23.972607"/>
      <origin rpy="0 0 0" xyz="-0.020386 0 0.075697"/>
      <inertia ixx="1.293" ixy="-0.00005897" ixz="0.07241" iyy="1.521" iyz="0.0000000617" izz="2.615"/>
    </inertial>
  </link>
  <!-- Belki -->
  <link name="right_rocker_beam">
    <visual>
      <geometry>
        <mesh filename="meshes/beam_full.stl" scale="0.001 0.001 0.001"/>
      </geometry>
      <origin rpy="0 0 0" xyz="0 0 0"/>
      <material name="black"/>
    </visual>
    <collision>
      <geometry>
        <mesh filename="meshes/beam_full.stl" scale="0.001 0.001 0.001"/>
      </geometry>
      <origin rpy="0 0 0" xyz="0 0 0"/>
    </collision>
    <inertial>
      <mass value="3.38412"/>
      <origin rpy="0 0 0" xyz="-0.000000009 -0.027628 -0.071329"/>
      <inertia ixx="0.01030" ixy="1e-12" ixz="-5e-12" iyy="0.05174" iyz="-0.002614" izz="0.04833"/>
    </inertial>
  </link>
  <joint name="right_rocker_beam_joint" type="revolute">
    <parent link="base_link"/>
    <child link="right_rocker_beam"/>
    <origin rpy="0 0 0" xyz="-0.13 -0.22085 0.0876"/>
    <axis xyz="0 1 0"/>
    <limit effort="50.0" lower="-0.2617993877991494" upper="0.2617993877991494" velocity="10.0"/>
    <dynamics damping="0.05" friction="0.005"/>
  </joint>
  <link name="left_rocker_beam">
    <visual>
      <geometry>
        <mesh filename="meshes/beam_full.stl" scale="0.001 0.001 0.001"/>
      </geometry>
      <origin rpy="0 0 0" xyz="0 0 0"/>
      <material name="black"/>
    </visual>
    <collision>
      <geometry>
        <mesh filename="meshes/beam_full.stl" scale="0.001 0.001 0.001"/>
      </geometry>
      <origin rpy="0 0 0" xyz="0 0 0"/>
    </collision>
    <inertial>
      <mass value="3.38412"/>
      <origin rpy="0 0 0" xyz="-0.000000009 -0.027628 -0.071329"/>
      <inertia ixx="0.01030" ixy="1e-12" ixz="-5e-12" iyy="0.05174" iyz="-0.002614" izz="0.04833"/>
    </inertial>
  </link>
  <joint name="left_rocker_beam_joint" type="revolute">
    <parent link="base_link"/>
    <child link="left_rocker_beam"/>
    <origin rpy="0 0 3.141592653589793" xyz="-0.13 0.22085 0.0876"/>
    <axis xyz="0 1 0"/>
    <limit effort="50.0" lower="-0.2617993877991494" upper="0.2617993877991494" velocity="10.0"/>
    <dynamics damping="0.05" friction="0.005"/>
  </joint>
  <link name="left_wheel_1">
    <visual>
      <geometry>
        <mesh filename="meshes/wheel.dae" scale="0.001 0.001 0.001"/>
      </geometry>
      <origin rpy="0 0 0" xyz="0 0 0"/>
      <material name="black"/>
    </visual>
    <collision>
      <geometry>
        <mesh filename="meshes/wheel.dae" scale="0.001 0.001 0.001"/>
      </geometry>
      <origin rpy="0 0 0" xyz="0 0 0"/>
    </collision>
    <inertial>
      <mass value="1.341411"/>
      <origin rpy="0 0 0" xyz="0.000003 0.005392 0.000000"/>
      <inertia ixx="0.002637" ixy="1.18e-9" ixz="8.32e-9" iyy="0.004379" iyz="-3.867e-9" izz="0.002637"/>
    </inertial>
  </link>
  <gazebo reference="left_wheel_1">
    <mu1>1.0</mu1>
    <mu2>1.0</mu2>
    <kp>100000.0</kp>
    <kd>50.0</kd>
    <minDepth>0.001</minDepth>
    <maxVel>0.1</maxVel>
  </gazebo>
  <joint name="left_wheel_1_joint" type="continuous">
    <parent link="base_link"/>
    <child link="left_wheel_1"/>
    <origin rpy="0 0 3.141592653589793" xyz="0.26 0.275 -0.0106"/>
    <axis xyz="0 -1 0"/>
    <limit effort="12.0" velocity="50.26548245743669"/>
    <dynamics damping="0.01" friction="0.001"/>
  </joint>
  <transmission name="left_wheel_1_trans">
    <type>transmission_interface/SimpleTransmission</type>
    <joint name="left_wheel_1_joint">
      <hardwareInterface>hardware_interface/VelocityJointInterface</hardwareInterface>
    </joint>
    <actuator name="left_wheel_1_motor">
      <hardwareInterface>hardware_interface/VelocityJointInterface</hardwareInterface>
      <mechanicalReduction>1</mechanicalReduction>
    </actuator>
  </transmission>
  <link name="left_wheel_2">
    <visual>
      <geometry>
        <mesh filename="meshes/wheel.dae" scale="0.001 0.001 0.001"/>
      </geometry>
      <origin rpy="0 0 0" xyz="0 0 0"/>
      <material name="black"/>
    </visual>
    <collision>
      <geometry>
        <mesh filename="meshes/wheel.dae" scale="0.001 0.001 0.001"/>
      </geometry>
      <origin rpy="0 0 0" xyz="0 0 0"/>
    </collision>
    <inertial>
      <mass value="1.341411"/>
      <origin rpy="0 0 0" xyz="0.000003 0.005392 0.000000"/>
      <inertia ixx="0.002637" ixy="1.18e-9" ixz="8.32e-9" iyy="0.004379" iyz="-3.867e-9" izz="0.002637"/>
    </inertial>
  </link>
  <gazebo reference="left_wheel_2">
    <mu1>1.0</mu1>
    <mu2>1.0</mu2>
    <kp>100000.0</kp>
    <kd>50.0</kd>
    <minDepth>0.001</minDepth>
    <maxVel>0.1</maxVel>
  </gazebo>
  <joint name="left_wheel_2_joint" type="continuous">
    <parent link="left_rocker_beam"/>
    <child link="left_wheel_2"/>
    <origin rpy="0 0 0.0" xyz="0.13 -0.05415 -0.0982"/>
    <axis xyz="0 -1 0"/>
    <limit effort="12.0" velocity="50.26548245743669"/>
    <dynamics damping="0.01" friction="0.001"/>
  </joint>
  <transmission name="left_wheel_2_trans">
    <type>transmission_interface/SimpleTransmission</type>
    <joint name="left_wheel_2_joint">
      <hardwareInterface>hardware_interface/VelocityJointInterface</hardwareInterface>
    </joint>
    <actuator name="left_wheel_2_motor">
      <hardwareInterface>hardware_interface/VelocityJointInterface</hardwareInterface>
      <mechanicalReduction>1</mechanicalReduction>
    </actuator>
  </transmission>
  <link name="left_wheel_3">
    <visual>
      <geometry>
        <mesh filename="meshes/wheel.dae" scale="0.001 0.001 0.001"/>
      </geometry>
      <origin rpy="0 0 0" xyz="0 0 0"/>
      <material name="black"/>
    </visual>
    <collision>
      <geometry>
        <mesh filename="meshes/wheel.dae" scale="0.001 0.001 0.001"/>
      </geometry>
      <origin rpy="0 0 0" xyz="0 0 0"/>
    </collision>
    <inertial>
      <mass value="1.341411"/>
      <origin rpy="0 0 0" xyz="0.000003 0.005392 0.000000"/>
      <inertia ixx="0.002637" ixy="1.18e-9" ixz="8.32e-9" iyy="0.004379" iyz="-3.867e-9" izz="0.002637"/>
    </inertial>
  </link>
  <gazebo reference="left_wheel_3">
    <mu1>1.0</mu1>
    <mu2>1.0</mu2>
    <kp>100000.0</kp>
    <kd>50.0</kd>
    <minDepth>0.001</minDepth>
    <maxVel>0.1</maxVel>
  </gazebo>
  <joint name="left_wheel_3_joint" type="continuous">
    <parent link="left_rocker_beam"/>
    <child link="left_wheel_3"/>
    <origin rpy="0 0 0.0" xyz="-0.13 -0.05415 -0.0982"/>
    <axis xyz="0 -1 0"/>
    <limit effort="12.0" velocity="50.26548245743669"/>
    <dynamics damping="0.01" friction="0.001"/>
  </joint>
  <transmission name="left_wheel_3_trans">
    <type>transmission_interface/SimpleTransmission</type>
    <joint name="left_wheel_3_joint">
      <hardwareInterface>hardware_interface/VelocityJointInterface</hardwareInterface>
    </joint>
    <actuator name="left_wheel_3_motor">
      <hardwareInterface>hardware_interface/VelocityJointInterface</hardwareInterface>
      <mechanicalReduction>1</mechanicalReduction>
    </actuator>
  </transmission>
  <link name="right_wheel_1">
    <visual>
      <geometry>
        <mesh filename="meshes/wheel.dae" scale="0.001 0.001 0.001"/>
      </geometry>
      <origin rpy="0 0 0" xyz="0 0 0"/>
      <material name="black"/>
    </visual>
    <collision>
      <geometry>
        <mesh filename="meshes/wheel.dae" scale="0.001 0.001 0.001"/>
      </geometry>
      <origin rpy="0 0 0" xyz="0 0 0"/>
    </collision>
    <inertial>
      <mass value="1.341411"/>
      <origin rpy="0 0 0" xyz="0.000003 0.005392 0.000000"/>
      <inertia ixx="0.002637" ixy="1.18e-9" ixz="8.32e-9" iyy="0.004379" iyz="-3.867e-9" izz="0.002637"/>
    </inertial>
  </link>
  <gazebo reference="right_wheel_1">
    <mu1>1.0</mu1>
    <mu2>1.0</mu2>
    <kp>100000.0</kp>
    <kd>50.0</kd>
    <minDepth>0.001</minDepth>
    <maxVel>0.1</maxVel>
  </gazebo>
  <joint name="right_wheel_1_joint" type="continuous">
    <parent link="base_link"/>
    <child link="right_wheel_1"/>
    <origin rpy="0 0 0.0" xyz="0.26 -0.275 -0.0106"/>
    <axis xyz="0 1 0"/>
    <limit effort="12.0" velocity="50.26548245743669"/>
    <dynamics damping="0.01" friction="0.001"/>
  </joint>
  <transmission name="right_wheel_1_trans">
    <type>transmission_interface/SimpleTransmission</type>
    <joint name="right_wheel_1_joint">
      <hardwareInterface>hardware_interface/VelocityJointInterface</hardwareInterface>
    </joint>
    <actuator name="right_wheel_1_motor">
      <hardwareInterface>hardware_interface/VelocityJointInterface</hardwareInterface>
      <mechanicalReduction>1</mechanicalReduction>
    </actuator>
  </transmission>
  <link name="right_wheel_2">
    <visual>
      <geometry>
        <mesh filename="meshes/wheel.dae" scale="0.001 0.001 0.001"/>
      </geometry>
      <origin rpy="0 0 0" xyz="0 0 0"/>
      <material name="black"/>
    </visual>
    <collision>
      <geometry>
        <mesh filename="meshes/wheel.dae" scale="0.001 0.001 0.001"/>
      </geometry>
      <origin rpy="0 0 0" xyz="0 0 0"/>
    </collision>
    <inertial>
      <mass value="1.341411"/>
      <origin rpy="0 0 0" xyz="0.000003 0.005392 0.000000"/>
      <inertia ixx="0.002637" ixy="1.18e-9" ixz="8.32e-9" iyy="0.004379" iyz="-3.867e-9" izz="0.002637"/>
    </inertial>
  </link>
  <gazebo reference="right_wheel_2">
    <mu1>1.0</mu1>
    <mu2>1.0</mu2>
    <kp>100000.0</kp>
    <kd>50.0</kd>
    <minDepth>0.001</minDepth>
    <maxVel>0.1</maxVel>
  </gazebo>
  <joint name="right_wheel_2_joint" type="continuous">
    <parent link="right_rocker_beam"/>
    <child link="right_wheel_2"/>
    <origin rpy="0 0 0.0" xyz="0.13 -0.05415 -0.0982"/>
    <axis xyz="0 1 0"/>
    <limit effort="12.0" velocity="50.26548245743669"/>
    <dynamics damping="0.01" friction="0.001"/>
  </joint>
  <transmission name="right_wheel_2_trans">
    <type>transmission_interface/SimpleTransmission</type>
    <joint name="right_wheel_2_joint">
      <hardwareInterface>hardware_interface/VelocityJointInterface</hardwareInterface>
    </joint>
    <actuator name="right_wheel_2_motor">
      <hardwareInterface>hardware_interface/VelocityJointInterface</hardwareInterface>
      <mechanicalReduction>1</mechanicalReduction>
    </actuator>
  </transmission>
  <link name="right_wheel_3">
    <visual>
      <geometry>
        <mesh filename="meshes/wheel.dae" scale="0.001 0.001 0.001"/>
      </geometry>
      <origin rpy="0 0 0" xyz="0 0 0"/>
      <material name="black"/>
    </visual>
    <collision>
      <geometry>
        <mesh filename="meshes/wheel.dae" scale="0.001 0.001 0.001"/>
      </geometry>
      <origin rpy="0 0 0" xyz="0 0 0"/>
    </collision>
    <inertial>
      <mass value="1.341411"/>
      <origin rpy="0 0 0" xyz="0.000003 0.005392 0.000000"/>
      <inertia ixx="0.002637" ixy="1.18e-9" ixz="8.32e-9" iyy="0.004379" iyz="-3.867e-9" izz="0.002637"/>
    </inertial>
  </link>
  <gazebo reference="right_wheel_3">
    <mu1>1.0</mu1>
    <mu2>1.0</mu2>
    <kp>100000.0</kp>
    <kd>50.0</kd>
    <minDepth>0.001</minDepth>
    <maxVel>0.1</maxVel>
  </gazebo>
  <joint name="right_wheel_3_joint" type="continuous">
    <parent link="right_rocker_beam"/>
    <child link="right_wheel_3"/>
    <origin rpy="0 0 0.0" xyz="-0.13 -0.05415 -0.0982"/>
    <axis xyz="0 1 0"/>
    <limit effort="12.0" velocity="50.26548245743669"/>
    <dynamics damping="0.01" friction="0.001"/>
  </joint>
  <transmission name="right_wheel_3_trans">
    <type>transmission_interface/SimpleTransmission</type>
    <joint name="right_wheel_3_joint">
      <hardwareInterface>hardware_interface/VelocityJointInterface</hardwareInterface>
    </joint>
    <actuator name="right_wheel_3_motor">
      <hardwareInterface>hardware_interface/VelocityJointInterface</hardwareInterface>
      <mechanicalReduction>1</mechanicalReduction>
    </actuator>
  </transmission>
  <!-- Gazebo - kolor -->
  <gazebo reference="left_wheel_1">
    <material>Gazebo/Black</material>
  </gazebo>
  <gazebo reference="left_wheel_2">
    <material>Gazebo/Black</material>
  </gazebo>
  <gazebo reference="left_wheel_3">
    <material>Gazebo/Black</material>
  </gazebo>
  <gazebo reference="right_wheel_1">
    <material>Gazebo/Black</material>
  </gazebo>
  <gazebo reference="right_wheel_2">
    <material>Gazebo/Black</material>
  </gazebo>
  <gazebo reference="right_wheel_3">
    <material>Gazebo/Black</material>
  </gazebo>
  <gazebo reference="left_rocker_beam">
    <material>Gazebo/Black</material>
  </gazebo>
  <gazebo reference="right_rocker_beam">
    <material>Gazebo/Black</material>
  </gazebo>
  <gazebo reference="base_link">
    <material>Gazebo/DarkGrey</material>
  </gazebo>
  <!-- Plugin ros2_control -->
  <gazebo>
    <plugin filename="libgazebo_ros2_control.so" name="gazebo_ros2_control">
      <update_rate>60</update_rate>
      <parameters>/workspaces/isaac_ros-dev/install/boxygo_controllers/share/boxygo_controllers/config/diff_drive_controller.yaml</parameters>
    </plugin>
  </gazebo>
  <!-- ros2_control hardware -->
  <ros2_control name="BoxyGoSystem" type="system">
    <hardware>
      <plugin>gazebo_ros2_control/GazeboSystem</plugin>
    </hardware>
    <joint name="left_wheel_1_joint">
      <command_interface name="velocity"/>
      <state_interface name="position"/>
      <state_interface name="velocity"/>
    </joint>
    <joint name="left_wheel_2_joint">
      <command_interface name="velocity"/>
      <state_interface name="position"/>
      <state_interface name="velocity"/>
    </joint>
    <joint name="left_wheel_3_joint">
      <command_interface name="velocity"/>
      <state_interface name="position"/>
      <state_interface name="velocity"/>
    </joint>
    <joint name="right_wheel_1_joint">
      <command_interface name="velocity"/>
      <state_interface name="position"/>
      <state_interface name="velocity"/>
    </joint>
    <joint name="right_wheel_2_joint">
      <command_interface name="velocity"/>
      <state_interface name="position"/>
      <state_interface name="velocity"/>
    </joint>
    <joint name="right_wheel_3_joint">
      <command_interface name="velocity"/>
      <state_interface name="position"/>
      <state_interface name="velocity"/>
    </joint>
    <joint name="left_rocker_beam_joint">
      <command_interface name="position"/>
      <state_interface name="position"/>
      <state_interface name="velocity"/>
    </joint>
    <joint name="right_rocker_beam_joint">
      <command_interface name="position"/>
      <state_interface name="position"/>
      <state_interface name="velocity"/>
    </joint>
  </ros2_control>
</robot>
