<?xml version="1.0" ?>
<!-- =================================================================================== -->
<!-- |    This document was autogenerated by xacro from robot_luksusowy_isaac.urdf.xacro | -->
<!-- |    EDITING THIS FILE BY HAND IS NOT RECOMMENDED                                 | -->
<!-- =================================================================================== -->
<robot name="delivery_robot">
  <!-- Materiały -->
  <material name="black">
    <color rgba="0.0 0.0 0.0 1.0"/>
  </material>
  <material name="white">
    <color rgba="0.7 0.7 0.7 0.5"/>
  </material>
  <material name="grey">
    <color rgba="0.4 0.4 0.4 1.0"/>
  </material>
  <material name="darkgrey">
    <color rgba="0.05 0.05 0.05 1.0"/>
  </material>
  <material name="aluminum">
    <color rgba="0.5 0.5 0.5 1"/>
  </material>
  <material name="plastic">
    <color rgba="0.1 0.1 0.1 1"/>
  </material>
  <!-- Rama -->
  <link name="base_link">
    <visual>
      <origin rpy="0 0 0" xyz="0 0 0"/>
      <geometry>
        <mesh filename="meshes/frame_full.stl" scale="0.001 0.001 0.001"/>
      </geometry>
      <material name="darkgrey"/>
    </visual>
    <collision>
      <origin rpy="0 0 0" xyz="0 0 0"/>
      <geometry>
        <mesh filename="meshes/frame_full.stl" scale="0.001 0.001 0.001"/>
      </geometry>
    </collision>
    <inertial>
      <mass value="23.972607"/>
      <origin rpy="0 0 0" xyz="-0.020386 0 0.075697"/>
      <inertia ixx="1.293" ixy="-0.00005897" ixz="0.07241" iyy="1.521" iyz="0.0000000617" izz="2.615"/>
    </inertial>
  </link>
  <!-- Belki -->
  <link name="right_rocker_beam">
    <visual>
      <geometry>
        <mesh filename="meshes/beam_full.stl" scale="0.001 0.001 0.001"/>
      </geometry>
      <origin rpy="0 0 0" xyz="0 0 0"/>
      <material name="black"/>
    </visual>
    <collision>
      <geometry>
        <mesh filename="meshes/beam_full.stl" scale="0.001 0.001 0.001"/>
      </geometry>
      <origin rpy="0 0 0" xyz="0 0 0"/>
    </collision>
    <inertial>
      <mass value="3.38412"/>
      <origin rpy="0 0 0" xyz="-0.000000009 -0.027628 -0.071329"/>
      <inertia ixx="0.01030" ixy="1e-12" ixz="-5e-12" iyy="0.05174" iyz="-0.002614" izz="0.04833"/>
    </inertial>
  </link>
  <joint name="right_rocker_beam_joint" type="revolute">
    <parent link="base_link"/>
    <child link="right_rocker_beam"/>
    <origin rpy="0 0 0" xyz="-0.13 -0.22085 0.0876"/>
    <axis xyz="0 1 0"/>
    <limit effort="50.0" lower="-0.2617993877991494" upper="0.2617993877991494" velocity="10.0"/>
    <dynamics damping="0.05" friction="0.005"/>
  </joint>
  <link name="left_rocker_beam">
    <visual>
      <geometry>
        <mesh filename="meshes/beam_full.stl" scale="0.001 0.001 0.001"/>
      </geometry>
      <origin rpy="0 0 0" xyz="0 0 0"/>
      <material name="black"/>
    </visual>
    <collision>
      <geometry>
        <mesh filename="meshes/beam_full.stl" scale="0.001 0.001 0.001"/>
      </geometry>
      <origin rpy="0 0 0" xyz="0 0 0"/>
    </collision>
    <inertial>
      <mass value="3.38412"/>
      <origin rpy="0 0 0" xyz="-0.000000009 -0.027628 -0.071329"/>
      <inertia ixx="0.01030" ixy="1e-12" ixz="-5e-12" iyy="0.05174" iyz="-0.002614" izz="0.04833"/>
    </inertial>
  </link>
  <joint name="left_rocker_beam_joint" type="revolute">
    <parent link="base_link"/>
    <child link="left_rocker_beam"/>
    <origin rpy="0 0 3.141592653589793" xyz="-0.13 0.22085 0.0876"/>
    <axis xyz="0 1 0"/>
    <limit effort="50.0" lower="-0.2617993877991494" upper="0.2617993877991494" velocity="10.0"/>
    <dynamics damping="0.05" friction="0.005"/>
  </joint>
  <link name="left_wheel_1">
    <visual>
      <geometry>
        <mesh filename="meshes/wheel.dae" scale="0.001 0.001 0.001"/>
      </geometry>
      <origin rpy="0 0 0" xyz="0 0 0"/>
      <material name="black"/>
    </visual>
    <collision>
      <geometry>
        <mesh filename="meshes/wheel.dae" scale="0.001 0.001 0.001"/>
      </geometry>
      <origin rpy="0 0 0" xyz="0 0 0"/>
    </collision>
    <inertial>
      <mass value="1.341411"/>
      <origin rpy="0 0 0" xyz="0.000003 0.005392 0.000000"/>
      <inertia ixx="0.002637" ixy="1.18e-9" ixz="8.32e-9" iyy="0.004379" iyz="-3.867e-9" izz="0.002637"/>
    </inertial>
  </link>
  <joint name="left_wheel_1_joint" type="continuous">
    <parent link="base_link"/>
    <child link="left_wheel_1"/>
    <origin rpy="0 0 3.141592653589793" xyz="0.26 0.275 -0.0106"/>
    <axis xyz="0 -1 0"/>
    <limit effort="12.0" velocity="50.26548245743669"/>
    <dynamics damping="0.01" friction="0.001"/>
  </joint>
  <link name="left_wheel_2">
    <visual>
      <geometry>
        <mesh filename="meshes/wheel.dae" scale="0.001 0.001 0.001"/>
      </geometry>
      <origin rpy="0 0 0" xyz="0 0 0"/>
      <material name="black"/>
    </visual>
    <collision>
      <geometry>
        <mesh filename="meshes/wheel.dae" scale="0.001 0.001 0.001"/>
      </geometry>
      <origin rpy="0 0 0" xyz="0 0 0"/>
    </collision>
    <inertial>
      <mass value="1.341411"/>
      <origin rpy="0 0 0" xyz="0.000003 0.005392 0.000000"/>
      <inertia ixx="0.002637" ixy="1.18e-9" ixz="8.32e-9" iyy="0.004379" iyz="-3.867e-9" izz="0.002637"/>
    </inertial>
  </link>
  <joint name="left_wheel_2_joint" type="continuous">
    <parent link="left_rocker_beam"/>
    <child link="left_wheel_2"/>
    <origin rpy="0 0 0.0" xyz="0.13 -0.05415 -0.0982"/>
    <axis xyz="0 -1 0"/>
    <limit effort="12.0" velocity="50.26548245743669"/>
    <dynamics damping="0.01" friction="0.001"/>
  </joint>
  <link name="left_wheel_3">
    <visual>
      <geometry>
        <mesh filename="meshes/wheel.dae" scale="0.001 0.001 0.001"/>
      </geometry>
      <origin rpy="0 0 0" xyz="0 0 0"/>
      <material name="black"/>
    </visual>
    <collision>
      <geometry>
        <mesh filename="meshes/wheel.dae" scale="0.001 0.001 0.001"/>
      </geometry>
      <origin rpy="0 0 0" xyz="0 0 0"/>
    </collision>
    <inertial>
      <mass value="1.341411"/>
      <origin rpy="0 0 0" xyz="0.000003 0.005392 0.000000"/>
      <inertia ixx="0.002637" ixy="1.18e-9" ixz="8.32e-9" iyy="0.004379" iyz="-3.867e-9" izz="0.002637"/>
    </inertial>
  </link>
  <joint name="left_wheel_3_joint" type="continuous">
    <parent link="left_rocker_beam"/>
    <child link="left_wheel_3"/>
    <origin rpy="0 0 0.0" xyz="-0.13 -0.05415 -0.0982"/>
    <axis xyz="0 -1 0"/>
    <limit effort="12.0" velocity="50.26548245743669"/>
    <dynamics damping="0.01" friction="0.001"/>
  </joint>
  <link name="right_wheel_1">
    <visual>
      <geometry>
        <mesh filename="meshes/wheel.dae" scale="0.001 0.001 0.001"/>
      </geometry>
      <origin rpy="0 0 0" xyz="0 0 0"/>
      <material name="black"/>
    </visual>
    <collision>
      <geometry>
        <mesh filename="meshes/wheel.dae" scale="0.001 0.001 0.001"/>
      </geometry>
      <origin rpy="0 0 0" xyz="0 0 0"/>
    </collision>
    <inertial>
      <mass value="1.341411"/>
      <origin rpy="0 0 0" xyz="0.000003 0.005392 0.000000"/>
      <inertia ixx="0.002637" ixy="1.18e-9" ixz="8.32e-9" iyy="0.004379" iyz="-3.867e-9" izz="0.002637"/>
    </inertial>
  </link>
  <joint name="right_wheel_1_joint" type="continuous">
    <parent link="base_link"/>
    <child link="right_wheel_1"/>
    <origin rpy="0 0 0.0" xyz="0.26 -0.275 -0.0106"/>
    <axis xyz="0 1 0"/>
    <limit effort="12.0" velocity="50.26548245743669"/>
    <dynamics damping="0.01" friction="0.001"/>
  </joint>
  <link name="right_wheel_2">
    <visual>
      <geometry>
        <mesh filename="meshes/wheel.dae" scale="0.001 0.001 0.001"/>
      </geometry>
      <origin rpy="0 0 0" xyz="0 0 0"/>
      <material name="black"/>
    </visual>
    <collision>
      <geometry>
        <mesh filename="meshes/wheel.dae" scale="0.001 0.001 0.001"/>
      </geometry>
      <origin rpy="0 0 0" xyz="0 0 0"/>
    </collision>
    <inertial>
      <mass value="1.341411"/>
      <origin rpy="0 0 0" xyz="0.000003 0.005392 0.000000"/>
      <inertia ixx="0.002637" ixy="1.18e-9" ixz="8.32e-9" iyy="0.004379" iyz="-3.867e-9" izz="0.002637"/>
    </inertial>
  </link>
  <joint name="right_wheel_2_joint" type="continuous">
    <parent link="right_rocker_beam"/>
    <child link="right_wheel_2"/>
    <origin rpy="0 0 0.0" xyz="0.13 -0.05415 -0.0982"/>
    <axis xyz="0 1 0"/>
    <limit effort="12.0" velocity="50.26548245743669"/>
    <dynamics damping="0.01" friction="0.001"/>
  </joint>
  <link name="right_wheel_3">
    <visual>
      <geometry>
        <mesh filename="meshes/wheel.dae" scale="0.001 0.001 0.001"/>
      </geometry>
      <origin rpy="0 0 0" xyz="0 0 0"/>
      <material name="black"/>
    </visual>
    <collision>
      <geometry>
        <mesh filename="meshes/wheel.dae" scale="0.001 0.001 0.001"/>
      </geometry>
      <origin rpy="0 0 0" xyz="0 0 0"/>
    </collision>
    <inertial>
      <mass value="1.341411"/>
      <origin rpy="0 0 0" xyz="0.000003 0.005392 0.000000"/>
      <inertia ixx="0.002637" ixy="1.18e-9" ixz="8.32e-9" iyy="0.004379" iyz="-3.867e-9" izz="0.002637"/>
    </inertial>
  </link>
  <joint name="right_wheel_3_joint" type="continuous">
    <parent link="right_rocker_beam"/>
    <child link="right_wheel_3"/>
    <origin rpy="0 0 0.0" xyz="-0.13 -0.05415 -0.0982"/>
    <axis xyz="0 1 0"/>
    <limit effort="12.0" velocity="50.26548245743669"/>
    <dynamics damping="0.01" friction="0.001"/>
  </joint>
  <!-- camera body, with origin at bottom screw mount -->
  <joint name="camera_joint" type="fixed">
    <origin rpy="0 0 0" xyz="0.35 0.0 0.30"/>
    <parent link="base_link"/>
    <child link="camera_bottom_screw_frame"/>
  </joint>
  <link name="camera_bottom_screw_frame"/>
  <joint name="camera_link_joint" type="fixed">
    <origin rpy="0 0 0" xyz="0.010600000000000002 0.0175 0.0125"/>
    <parent link="camera_bottom_screw_frame"/>
    <child link="camera_link"/>
  </joint>
  <link name="camera_link">
    <visual>
      <!-- the mesh origin is at front plate in between the two infrared camera axes -->
      <origin rpy="1.5707963267948966 0 1.5707963267948966" xyz="0.0043 -0.0175 0"/>
      <geometry>
        <mesh filename="file:///opt/ros/humble/share/realsense2_description/meshes/d435.dae"/>
      </geometry>
    </visual>
    <collision>
      <origin rpy="0 0 0" xyz="0 -0.0175 0"/>
      <geometry>
        <box size="0.02505 0.09 0.025"/>
      </geometry>
    </collision>
    <inertial>
      <!-- The following are not reliable values, and should not be used for modeling -->
      <mass value="0.072"/>
      <origin xyz="0 0 0"/>
      <inertia ixx="0.003881243" ixy="0.0" ixz="0.0" iyy="0.000498940" iyz="0.0" izz="0.003879257"/>
    </inertial>
  </link>
  <!-- camera depth joints and links -->
  <joint name="camera_depth_joint" type="fixed">
    <origin rpy="0 0 0" xyz="0 0 0"/>
    <parent link="camera_link"/>
    <child link="camera_depth_frame"/>
  </joint>
  <link name="camera_depth_frame"/>
  <joint name="camera_depth_optical_joint" type="fixed">
    <origin rpy="-1.5707963267948966 0 -1.5707963267948966" xyz="0 0 0"/>
    <parent link="camera_depth_frame"/>
    <child link="camera_depth_optical_frame"/>
  </joint>
  <link name="camera_depth_optical_frame"/>
  <!-- camera left IR joints and links -->
  <joint name="camera_infra1_joint" type="fixed">
    <origin rpy="0 0 0" xyz="0 0.0 0"/>
    <parent link="camera_link"/>
    <child link="camera_infra1_frame"/>
  </joint>
  <link name="camera_infra1_frame"/>
  <joint name="camera_infra1_optical_joint" type="fixed">
    <origin rpy="-1.5707963267948966 0 -1.5707963267948966" xyz="0 0 0"/>
    <parent link="camera_infra1_frame"/>
    <child link="camera_infra1_optical_frame"/>
  </joint>
  <link name="camera_infra1_optical_frame"/>
  <!-- camera right IR joints and links -->
  <joint name="camera_infra2_joint" type="fixed">
    <origin rpy="0 0 0" xyz="0 -0.05 0"/>
    <parent link="camera_link"/>
    <child link="camera_infra2_frame"/>
  </joint>
  <link name="camera_infra2_frame"/>
  <joint name="camera_infra2_optical_joint" type="fixed">
    <origin rpy="-1.5707963267948966 0 -1.5707963267948966" xyz="0 0 0"/>
    <parent link="camera_infra2_frame"/>
    <child link="camera_infra2_optical_frame"/>
  </joint>
  <link name="camera_infra2_optical_frame"/>
  <!-- camera color joints and links -->
  <joint name="camera_color_joint" type="fixed">
    <origin rpy="0 0 0" xyz="0 0.015 0"/>
    <parent link="camera_link"/>
    <child link="camera_color_frame"/>
  </joint>
  <link name="camera_color_frame"/>
  <joint name="camera_color_optical_joint" type="fixed">
    <origin rpy="-1.5707963267948966 0 -1.5707963267948966" xyz="0 0 0"/>
    <parent link="camera_color_frame"/>
    <child link="camera_color_optical_frame"/>
  </joint>
  <link name="camera_color_optical_frame"/>
  <link name="camera_accel_frame"/>
  <link name="camera_accel_optical_frame"/>
  <link name="camera_gyro_frame"/>
  <link name="camera_gyro_optical_frame"/>
  <joint name="camera_accel_joint" type="fixed">
    <origin rpy="0 0 0" xyz="-0.01174 -0.00552 0.0051"/>
    <parent link="camera_link"/>
    <child link="camera_accel_frame"/>
  </joint>
  <joint name="camera_accel_optical_joint" type="fixed">
    <origin rpy="-1.5707963267948966 0 -1.5707963267948966" xyz="0 0 0"/>
    <parent link="camera_accel_frame"/>
    <child link="camera_accel_optical_frame"/>
  </joint>
  <joint name="camera_gyro_joint" type="fixed">
    <origin rpy="0 0 0" xyz="-0.01174 -0.00552 0.0051"/>
    <parent link="camera_link"/>
    <child link="camera_gyro_frame"/>
  </joint>
  <joint name="camera_gyro_optical_joint" type="fixed">
    <origin rpy="-1.5707963267948966 0 -1.5707963267948966" xyz="0 0 0"/>
    <parent link="camera_gyro_frame"/>
    <child link="camera_gyro_optical_frame"/>
  </joint>
</robot>
